Workbook

Sheet Assumptions
A1: THREE-STATEMENT ANALYSIS MODEL
A2: Illustrative values | Dynamic scenarios | INR crores
A4: Selected Scenario | B4: =Dashboard!B3 -> Base
A5: Model Units | B5: INR crores
A7: SCENARIO DRIVERS
A8: Driver | B8: Base | C8: Optimistic | D8: Pessimistic | E8: Selected
A9: Revenue Growth | B9: 0.08 | C9: 0.12 | D9: 0.03 | E9: =INDEX(B9:D9,1,MATCH($B$4,$B$8:$D$8,0)) -> 0.08
A10: COGS as % Revenue | B10: 0.58 | C10: 0.54 | D10: 0.63 | E10: =INDEX(B10:D10,1,MATCH($B$4,$B$8:$D$8,0)) -> 0.58
A11: Operating Expenses as % Revenue | B11: 0.2 | C11: 0.18 | D11: 0.23 | E11: =INDEX(B11:D11,1,MATCH($B$4,$B$8:$D$8,0)) -> 0.2
A12: Tax Rate | B12: 0.25 | C12: 0.23 | D12: 0.27 | E12: =INDEX(B12:D12,1,MATCH($B$4,$B$8:$D$8,0)) -> 0.25
A13: Interest Rate | B13: 0.06 | C13: 0.05 | D13: 0.075 | E13: =INDEX(B13:D13,1,MATCH($B$4,$B$8:$D$8,0)) -> 0.06
A14: CapEx as % Revenue | B14: 0.07 | C14: 0.08 | D14: 0.05 | E14: =INDEX(B14:D14,1,MATCH($B$4,$B$8:$D$8,0)) -> 0.07
A15: Depreciation as % Opening PP&E | B15: 0.1 | C15: 0.09 | D15: 0.11 | E15: =INDEX(B15:D15,1,MATCH($B$4,$B$8:$D$8,0)) -> 0.1
A16: AR Days | B16: 42 | C16: 38 | D16: 50 | E16: =INDEX(B16:D16,1,MATCH($B$4,$B$8:$D$8,0)) -> 42
A17: Inventory Days | B17: 55 | C17: 48 | D17: 65 | E17: =INDEX(B17:D17,1,MATCH($B$4,$B$8:$D$8,0)) -> 55
A18: AP Days | B18: 40 | C18: 45 | D18: 35 | E18: =INDEX(B18:D18,1,MATCH($B$4,$B$8:$D$8,0)) -> 40
A20: OPENING BALANCES & FINANCING
A21: Opening Revenue | B21: 1000
A22: Opening Cash | B22: 120
A23: Opening Accounts Receivable | B23: 120
A24: Opening Inventory | B24: 100
A25: Opening PP&E | B25: 500
A26: Opening Accounts Payable | B26: 90
A27: Opening Debt | B27: 250
A28: Opening Share Capital | B28: 300
A29: Opening Retained Earnings | B29: 200
A30: Annual Debt Issuance | B30: 20
A31: Annual Debt Repayment | B31: 15
A32: Dividend Payout Ratio | B32: 0.2

Sheet Income Statement
A1: INCOME STATEMENT
A2: INR crores | Illustrative analysis
A4: Fiscal Year | B4: FY2025A | C4: FY2026 | D4: FY2027 | E4: FY2028 | F4: FY2029
A5: Revenue | B5: =Assumptions!$B$21 -> 1000 | C5: =B5*(1+Assumptions!$E$9) -> 1080 | D5: =C5*(1+Assumptions!$E$9) -> 1166.4 | E5: =D5*(1+Assumptions!$E$9) -> 1259.712 | F5: =E5*(1+Assumptions!$E$9) -> 1360.489
A6: Revenue Growth | C6: =C5/B5-1 -> 0.08 | D6: =D5/C5-1 -> 0.08 | E6: =E5/D5-1 -> 0.08 | F6: =F5/E5-1 -> 0.08
A8: COGS | B8: =B5*Assumptions!$E$10 -> 580 | C8: =C5*Assumptions!$E$10 -> 626.4 | D8: =D5*Assumptions!$E$10 -> 676.512 | E8: =E5*Assumptions!$E$10 -> 730.63296 | F8: =F5*Assumptions!$E$10 -> 789.0836
A9: Gross Profit | B9: =B5-B8 -> 420 | C9: =C5-C8 -> 453.6 | D9: =D5-D8 -> 489.888 | E9: =E5-E8 -> 529.07904 | F9: =F5-F8 -> 571.40536
A10: Gross Margin | B10: =B9/B5 -> 0.42 | C10: =C9/C5 -> 0.42 | D10: =D9/D5 -> 0.42 | E10: =E9/E5 -> 0.42 | F10: =F9/F5 -> 0.42
A11: Operating Expenses | B11: =B5*Assumptions!$E$11 -> 200 | C11: =C5*Assumptions!$E$11 -> 216 | D11: =D5*Assumptions!$E$11 -> 233.28 | E11: =E5*Assumptions!$E$11 -> 251.9424 | F11: =F5*Assumptions!$E$11 -> 272.09779
A12: EBITDA | B12: =B9-B11 -> 220 | C12: =C9-C11 -> 237.6 | D12: =D9-D11 -> 256.608 | E12: =E9-E11 -> 277.13664 | F12: =F9-F11 -> 299.30757
A13: EBITDA Margin | B13: =B12/B5 -> 0.22 | C13: =C12/C5 -> 0.22 | D13: =D12/D5 -> 0.22 | E13: =E12/E5 -> 0.22 | F13: =F12/F5 -> 0.22
A14: Depreciation | B14: =Assumptions!$B$25*Assumptions!$E$15 -> 50 | C14: ='Balance Sheet'!B8*Assumptions!$E$15 -> 50 | D14: ='Balance Sheet'!C8*Assumptions!$E$15 -> 52.56 | E14: ='Balance Sheet'!D8*Assumptions!$E$15 -> 55.4688 | F14: ='Balance Sheet'!E8*Assumptions!$E$15 -> 58.739904
A15: EBIT | B15: =B12-B14 -> 170 | C15: =C12-C14 -> 187.6 | D15: =D12-D14 -> 204.048 | E15: =E12-E14 -> 221.66784 | F15: =F12-F14 -> 240.56767
A16: EBIT Margin | B16: =B15/B5 -> 0.17 | C16: =C15/C5 -> 0.1737037 | D16: =D15/D5 -> 0.17493827 | E16: =E15/E5 -> 0.17596708 | F16: =F15/F5 -> 0.17682442
A17: Interest Expense | B17: =Assumptions!$B$27*Assumptions!$E$13 -> 15 | C17: ='Balance Sheet'!B13*Assumptions!$E$13 -> 15 | D17: ='Balance Sheet'!C13*Assumptions!$E$13 -> 15.3 | E17: ='Balance Sheet'!D13*Assumptions!$E$13 -> 15.6 | F17: ='Balance Sheet'!E13*Assumptions!$E$13 -> 15.9
A18: Earnings Before Tax | B18: =B15-B17 -> 155 | C18: =C15-C17 -> 172.6 | D18: =D15-D17 -> 188.748 | E18: =E15-E17 -> 206.06784 | F18: =F15-F17 -> 224.66767
A19: Tax Expense | B19: =MAX(0,B18*Assumptions!$E$12) -> 38.75 | C19: =MAX(0,C18*Assumptions!$E$12) -> 43.15 | D19: =MAX(0,D18*Assumptions!$E$12) -> 47.187 | E19: =MAX(0,E18*Assumptions!$E$12) -> 51.51696 | F19: =MAX(0,F18*Assumptions!$E$12) -> 56.166917
A20: Net Income | B20: =B18-B19 -> 116.25 | C20: =C18-C19 -> 129.45 | D20: =D18-D19 -> 141.561 | E20: =E18-E19 -> 154.55088 | F20: =F18-F19 -> 168.50075
A21: Net Margin | B21: =B20/B5 -> 0.11625 | C21: =C20/C5 -> 0.11986111 | D21: =D20/D5 -> 0.12136574 | E21: =E20/E5 -> 0.12268747 | F21: =F20/F5 -> 0.12385308

Sheet Balance Sheet
A1: BALANCE SHEET
A2: INR crores | Integrated statement
A4: Fiscal Year | B4: FY2025A | C4: FY2026 | D4: FY2027 | E4: FY2028 | F4: FY2029
A5: Cash | B5: =Assumptions!$B$22 -> 120 | C5: ='Cash Flow Statement'!C25 -> 182.94356 | D5: ='Cash Flow Statement'!D25 -> 260.10305 | E5: ='Cash Flow Statement'!E25 -> 343.07129 | F5: ='Cash Flow Statement'!F25 -> 432.37923
A6: Accounts Receivable | B6: =Assumptions!$B$23 -> 120 | C6: ='Income Statement'!C5*Assumptions!$E$16/365 -> 124.27397 | D6: ='Income Statement'!D5*Assumptions!$E$16/365 -> 134.21589 | E6: ='Income Statement'!E5*Assumptions!$E$16/365 -> 144.95316 | F6: ='Income Statement'!F5*Assumptions!$E$16/365 -> 156.54941
A7: Inventory | B7: =Assumptions!$B$24 -> 100 | C7: ='Income Statement'!C8*Assumptions!$E$17/365 -> 94.389041 | D7: ='Income Statement'!D8*Assumptions!$E$17/365 -> 101.94016 | E7: ='Income Statement'!E8*Assumptions!$E$17/365 -> 110.09538 | F7: ='Income Statement'!F8*Assumptions!$E$17/365 -> 118.90301
A8: Net PP&E | B8: =Assumptions!$B$25 -> 500 | C8: =B8+'Cash Flow Statement'!C13-'Income Statement'!C14 -> 525.6 | D8: =C8+'Cash Flow Statement'!D13-'Income Statement'!D14 -> 554.688 | E8: =D8+'Cash Flow Statement'!E13-'Income Statement'!E14 -> 587.39904 | F8: =E8+'Cash Flow Statement'!F13-'Income Statement'!F14 -> 623.89336
A9: Total Assets | B9: =SUM(B5:B8) -> 840 | C9: =SUM(C5:C8) -> 927.20658 | D9: =SUM(D5:D8) -> 1050.9471 | E9: =SUM(E5:E8) -> 1185.5189 | F9: =SUM(F5:F8) -> 1331.725
A11: LIABILITIES
A12: Accounts Payable | B12: =Assumptions!$B$26 -> 90 | C12: ='Income Statement'!C8*Assumptions!$E$18/365 -> 68.646575 | D12: ='Income Statement'!D8*Assumptions!$E$18/365 -> 74.138301 | E12: ='Income Statement'!E8*Assumptions!$E$18/365 -> 80.069365 | F12: ='Income Statement'!F8*Assumptions!$E$18/365 -> 86.474915
A13: Debt | B13: =Assumptions!$B$27 -> 250 | C13: =B13+'Cash Flow Statement'!C17-'Cash Flow Statement'!C18 -> 255 | D13: =C13+'Cash Flow Statement'!D17-'Cash Flow Statement'!D18 -> 260 | E13: =D13+'Cash Flow Statement'!E17-'Cash Flow Statement'!E18 -> 265 | F13: =E13+'Cash Flow Statement'!F17-'Cash Flow Statement'!F18 -> 270
A14: Total Liabilities | B14: =SUM(B12:B13) -> 340 | C14: =SUM(C12:C13) -> 323.64658 | D14: =SUM(D12:D13) -> 334.1383 | E14: =SUM(E12:E13) -> 345.06937 | F14: =SUM(F12:F13) -> 356.47491
A16: EQUITY
A17: Share Capital | B17: =Assumptions!$B$28 -> 300 | C17: =B17 -> 300 | D17: =C17 -> 300 | E17: =D17 -> 300 | F17: =E17 -> 300
A18: Retained Earnings | B18: =Assumptions!$B$29 -> 200 | C18: =B18+'Income Statement'!C20-'Cash Flow Statement'!C19 -> 303.56 | D18: =C18+'Income Statement'!D20-'Cash Flow Statement'!D19 -> 416.8088 | E18: =D18+'Income Statement'!E20-'Cash Flow Statement'!E19 -> 540.4495 | F18: =E18+'Income Statement'!F20-'Cash Flow Statement'!F19 -> 675.2501
A19: Total Equity | B19: =SUM(B17:B18) -> 500 | C19: =SUM(C17:C18) -> 603.56 | D19: =SUM(D17:D18) -> 716.8088 | E19: =SUM(E17:E18) -> 840.4495 | F19: =SUM(F17:F18) -> 975.2501
A20: Total Liabilities & Equity | B20: =B14+B19 -> 840 | C20: =C14+C19 -> 927.20658 | D20: =D14+D19 -> 1050.9471 | E20: =E14+E19 -> 1185.5189 | F20: =F14+F19 -> 1331.725
A22: Balance Check | B22: =B9-B20 -> 0 | C22: =C9-C20 -> 0 | D22: =D9-D20 -> 0 | E22: =E9-E20 -> 0 | F22: =F9-F20 -> 0

Sheet Cash Flow Statement
A1: CASH FLOW STATEMENT
A2: INR crores | Indirect method
A4: Fiscal Year | B4: FY2025A | C4: FY2026 | D4: FY2027 | E4: FY2028 | F4: FY2029
A5: Net Income | C5: ='Income Statement'!C20 -> 129.45 | D5: ='Income Statement'!D20 -> 141.561 | E5: ='Income Statement'!E20 -> 154.55088 | F5: ='Income Statement'!F20 -> 168.50075
A6: Depreciation | C6: ='Income Statement'!C14 -> 50 | D6: ='Income Statement'!D14 -> 52.56 | E6: ='Income Statement'!E14 -> 55.4688 | F6: ='Income Statement'!F14 -> 58.739904
A7: Change in Accounts Receivable | C7: =-('Balance Sheet'!C6-'Balance Sheet'!B6) -> -4.2739726 | D7: =-('Balance Sheet'!D6-'Balance Sheet'!C6) -> -9.9419178 | E7: =-('Balance Sheet'!E6-'Balance Sheet'!D6) -> -10.737271 | F7: =-('Balance Sheet'!F6-'Balance Sheet'!E6) -> -11.596253
A8: Change in Inventory | C8: =-('Balance Sheet'!C7-'Balance Sheet'!B7) -> 5.6109589 | D8: =-('Balance Sheet'!D7-'Balance Sheet'!C7) -> -7.5511233 | E8: =-('Balance Sheet'!E7-'Balance Sheet'!D7) -> -8.1552132 | F8: =-('Balance Sheet'!F7-'Balance Sheet'!E7) -> -8.8076302
A9: Change in Accounts Payable | C9: ='Balance Sheet'!C12-'Balance Sheet'!B12 -> -21.353425 | D9: ='Balance Sheet'!D12-'Balance Sheet'!C12 -> 5.491726 | E9: ='Balance Sheet'!E12-'Balance Sheet'!D12 -> 5.9310641 | F9: ='Balance Sheet'!F12-'Balance Sheet'!E12 -> 6.4055492
A11: Cash Flow from Operations | C11: =SUM(C5:C9) -> 159.43356 | D11: =SUM(D5:D9) -> 182.11968 | E11: =SUM(E5:E9) -> 197.05826 | F11: =SUM(F5:F9) -> 213.24232
A13: Capital Expenditures | C13: ='Income Statement'!C5*Assumptions!$E$14 -> 75.6 | D13: ='Income Statement'!D5*Assumptions!$E$14 -> 81.648 | E13: ='Income Statement'!E5*Assumptions!$E$14 -> 88.17984 | F13: ='Income Statement'!F5*Assumptions!$E$14 -> 95.234227
A15: Cash Flow from Investing | C15: =-C13 -> -75.6 | D15: =-D13 -> -81.648 | E15: =-E13 -> -88.17984 | F15: =-F13 -> -95.234227
A17: Debt Issuance | C17: =Assumptions!$B$30 -> 20 | D17: =Assumptions!$B$30 -> 20 | E17: =Assumptions!$B$30 -> 20 | F17: =Assumptions!$B$30 -> 20
A18: Debt Repayment | C18: =MIN(Assumptions!$B$31,'Balance Sheet'!B13+C17) -> 15 | D18: =MIN(Assumptions!$B$31,'Balance Sheet'!C13+D17) -> 15 | E18: =MIN(Assumptions!$B$31,'Balance Sheet'!D13+E17) -> 15 | F18: =MIN(Assumptions!$B$31,'Balance Sheet'!E13+F17) -> 15
A19: Dividends | C19: =MAX(0,'Income Statement'!C20*Assumptions!$B$32) -> 25.89 | D19: =MAX(0,'Income Statement'!D20*Assumptions!$B$32) -> 28.3122 | E19: =MAX(0,'Income Statement'!E20*Assumptions!$B$32) -> 30.910176 | F19: =MAX(0,'Income Statement'!F20*Assumptions!$B$32) -> 33.70015
A21: Cash Flow from Financing | C21: =C17-C18-C19 -> -20.89 | D21: =D17-D18-D19 -> -23.3122 | E21: =E17-E18-E19 -> -25.910176 | F21: =F17-F18-F19 -> -28.70015
A23: Net Change in Cash | C23: =C11+C15+C21 -> 62.943562 | D23: =D11+D15+D21 -> 77.159485 | E23: =E11+E15+E21 -> 82.968244 | F23: =F11+F15+F21 -> 89.307943
A24: Beginning Cash | B24: ='Balance Sheet'!B5 -> 120 | C24: ='Balance Sheet'!B5 -> 120 | D24: ='Balance Sheet'!C5 -> 182.94356 | E24: ='Balance Sheet'!D5 -> 260.10305 | F24: ='Balance Sheet'!E5 -> 343.07129
A25: Ending Cash | B25: ='Balance Sheet'!B5 -> 120 | C25: =C24+C23 -> 182.94356 | D25: =D24+D23 -> 260.10305 | E25: =E24+E23 -> 343.07129 | F25: =F24+F23 -> 432.37923
A26: Cash Tie-Out | B26: =B25-'Balance Sheet'!B5 -> 0 | C26: =C25-'Balance Sheet'!C5 -> 0 | D26: =D25-'Balance Sheet'!D5 -> 0 | E26: =E25-'Balance Sheet'!E5 -> 0 | F26: =F25-'Balance Sheet'!F5 -> 0

Sheet Dashboard
A1: THREE-STATEMENT ANALYSIS DASHBOARD
A2: INR crores | Dynamic operating, profitability, liquidity and leverage analysis
A3: Selected Scenario | B3: Base
A5: KEY PERFORMANCE INDICATORS
A6: Revenue CAGR | B6: Net Margin | C6: Return on Equity | D6: Return on Assets | E6: Debt / Equity | F6: Balance Status | G6: Cash Status
A7: =('Income Statement'!F5/'Income Statement'!B5)^(1/4)-1 -> 0.08 | B7: ='Income Statement'!F21 -> 0.12385308 | C7: ='Income Statement'!F20/AVERAGE('Balance Sheet'!E19:F19) -> 0.18560422 | D7: ='Income Statement'!F20/AVERAGE('Balance Sheet'!E9:F9) -> 0.13387718 | E7: ='Balance Sheet'!F13/'Balance Sheet'!F19 -> 0.27685206 | F7: {=IF(MAX(ABS('Balance Sheet'!B22:F22))<0.1,"PASS","REVIEW")} -> PASS | G7: {=IF(MAX(ABS('Cash Flow Statement'!B26:F26))<0.1,"PASS","REVIEW")} -> PASS
A9: Analysis focuses on formula linkages, scenario switching, ratio analysis and statement reconciliation.
A11: CHART DATA — INR CRORES
A12: Metric | B12: FY2025A | C12: FY2026 | D12: FY2027 | E12: FY2028 | F12: FY2029 | L12: KEY PERFORMANCE INDICATORS
A13: Revenue | B13: ='Income Statement'!B5 -> 1000 | C13: ='Income Statement'!C5 -> 1080 | D13: ='Income Statement'!D5 -> 1166.4 | E13: ='Income Statement'!E5 -> 1259.712 | F13: ='Income Statement'!F5 -> 1360.489
A14: EBITDA Margin | B14: ='Income Statement'!B13 -> 0.22 | C14: ='Income Statement'!C13 -> 0.22 | D14: ='Income Statement'!D13 -> 0.22 | E14: ='Income Statement'!E13 -> 0.22 | F14: ='Income Statement'!F13 -> 0.22
A15: Operating Cash Flow | C15: ='Cash Flow Statement'!C11 -> 159.43356 | D15: ='Cash Flow Statement'!D11 -> 182.11968 | E15: ='Cash Flow Statement'!E11 -> 197.05826 | F15: ='Cash Flow Statement'!F11 -> 213.24232
A16: Debt / Equity | B16: ='Balance Sheet'!B13/'Balance Sheet'!B19 -> 0.5 | C16: ='Balance Sheet'!C13/'Balance Sheet'!C19 -> 0.42249321 | D16: ='Balance Sheet'!D13/'Balance Sheet'!D19 -> 0.36271876 | E16: ='Balance Sheet'!E13/'Balance Sheet'!E19 -> 0.31530746 | F16: ='Balance Sheet'!F13/'Balance Sheet'!F19 -> 0.27685206
A18: SENSITIVITY: REVENUE GROWTH VS EBITDA MARGIN
A19: Growth / Margin | B19: 0.34 | C19: 0.38 | D19: 0.42 | E19: 0.46 | F19: 0.5
A20: 0 | B20: =$B$19+$A20 -> 0.34 | C20: =$C$19+$A20 -> 0.38 | D20: =$D$19+$A20 -> 0.42 | E20: =$E$19+$A20 -> 0.46 | F20: =$F$19+$A20 -> 0.5
A21: 0.03 | B21: =$B$19+$A21 -> 0.37 | C21: =$C$19+$A21 -> 0.41 | D21: =$D$19+$A21 -> 0.45 | E21: =$E$19+$A21 -> 0.49 | F21: =$F$19+$A21 -> 0.53
A22: 0.06 | B22: =$B$19+$A22 -> 0.4 | C22: =$C$19+$A22 -> 0.44 | D22: =$D$19+$A22 -> 0.48 | E22: =$E$19+$A22 -> 0.52 | F22: =$F$19+$A22 -> 0.56
A23: 0.09 | B23: =$B$19+$A23 -> 0.43 | C23: =$C$19+$A23 -> 0.47 | D23: =$D$19+$A23 -> 0.51 | E23: =$E$19+$A23 -> 0.55 | F23: =$F$19+$A23 -> 0.59
A24: 0.12 | B24: =$B$19+$A24 -> 0.46 | C24: =$C$19+$A24 -> 0.5 | D24: =$D$19+$A24 -> 0.54 | E24: =$E$19+$A24 -> 0.58 | F24: =$F$19+$A24 -> 0.62
A26: Cash Flow Bridge — INR Crores | B26: FY2029
A27: Cash from Operations | B27: ='Cash Flow Statement'!F11 -> 213.24232
A28: Cash from Investing | B28: ='Cash Flow Statement'!F15 -> -95.234227
A29: Cash from Financing | B29: ='Cash Flow Statement'!F21 -> -28.70015
A30: Net Change in Cash | B30: ='Cash Flow Statement'!F23 -> 89.307943

Sheet DCF
A1: ILLUSTRATIVE DCF VALUATION MODEL
A2: INR crores | Unlevered FCF | Mid-year convention | Prepared 16-Aug-2026
A4: VALUATION CONTROLS | B4: Value | C4: Source / Rationale
A5: Selected Case | B5: =Assumptions!B4 -> Base | C5: Linked to model scenario selector
A6: WACC | B6: =WACC!D32 -> 0.10765409 | C6: Linked from WACC sheet
A7: Terminal Growth Rate | B7: 0.03 | C7: Illustrative steady-state growth assumption
A8: Net Debt / (Net Cash) | B8: =WACC!B21 -> -162.37923 | C8: FY2029 forecast debt less cash
A9: Share Count Proxy | B9: =Assumptions!B28/100 -> 3 | C9: Share capital proxy divided by 100; replace with diluted shares (M)
A10: Valuation Basis | B10: Enterprise value and equity bridge; per-share output is a proxy until live share data is provided.
A12: UNLEVERED FREE CASH FLOW FORECAST | B12: FY2026E | C12: FY2027E | D12: FY2028E | E12: FY2029E | F12: FY2030E
A13: Fiscal Year | B13: FY2026E | C13: FY2027E | D13: FY2028E | E13: FY2029E | F13: FY2030E
A14: Revenue | B14: ='Income Statement'!C5 -> 1080 | C14: ='Income Statement'!D5 -> 1166.4 | D14: ='Income Statement'!E5 -> 1259.712 | E14: ='Income Statement'!F5 -> 1360.489 | F14: =E14*(1+Assumptions!$E$9) -> 1469.3281
A15: Revenue Growth | B15: =B14/'Income Statement'!B5-1 -> 0.08 | C15: =C14/B14-1 -> 0.08 | D15: =D14/C14-1 -> 0.08 | E15: =E14/D14-1 -> 0.08 | F15: =F14/E14-1 -> 0.08
A16: EBIT | B16: ='Income Statement'!C15 -> 187.6 | C16: ='Income Statement'!D15 -> 204.048 | D16: ='Income Statement'!E15 -> 221.66784 | E16: ='Income Statement'!F15 -> 240.56767 | F16: =F14*(1-Assumptions!$E$10-Assumptions!$E$11)-F19 -> 259.81308
A17: Tax Rate | B17: =Assumptions!$E$12 -> 0.25 | C17: =Assumptions!$E$12 -> 0.25 | D17: =Assumptions!$E$12 -> 0.25 | E17: =Assumptions!$E$12 -> 0.25 | F17: =Assumptions!$E$12 -> 0.25
A18: NOPAT | B18: =B16*(1-B17) -> 140.7 | C18: =C16*(1-C17) -> 153.036 | D18: =D16*(1-D17) -> 166.25088 | E18: =E16*(1-E17) -> 180.42575 | F18: =F16*(1-F17) -> 194.85981
A19: Depreciation | B19: ='Income Statement'!C14 -> 50 | C19: ='Income Statement'!D14 -> 52.56 | D19: ='Income Statement'!E14 -> 55.4688 | E19: ='Income Statement'!F14 -> 58.739904 | F19: =E19*(1+Assumptions!$E$9) -> 63.439096
A20: Capital Expenditures | B20: ='Cash Flow Statement'!C13 -> 75.6 | C20: ='Cash Flow Statement'!D13 -> 81.648 | D20: ='Cash Flow Statement'!E13 -> 88.17984 | E20: ='Cash Flow Statement'!F13 -> 95.234227 | F20: =F14*Assumptions!$E$14 -> 102.85297
A21: Change in NWC | B21: =(('Balance Sheet'!C6+'Balance Sheet'!C7-'Balance Sheet'!C12)-('Balance Sheet'!B6+'Balance Sheet'!B7-'Balance Sheet'!B12)) -> 20.016438 | C21: =(('Balance Sheet'!D6+'Balance Sheet'!D7-'Balance Sheet'!D12)-('Balance Sheet'!C6+'Balance Sheet'!C7-'Balance Sheet'!C12)) -> 12.001315 | D21: =(('Balance Sheet'!E6+'Balance Sheet'!E7-'Balance Sheet'!E12)-('Balance Sheet'!D6+'Balance Sheet'!D7-'Balance Sheet'!D12)) -> 12.96142 | E21: =(('Balance Sheet'!F6+'Balance Sheet'!F7-'Balance Sheet'!F12)-('Balance Sheet'!E6+'Balance Sheet'!E7-'Balance Sheet'!E12)) -> 13.998334 | F21: =(F14*Assumptions!$E$16/365+F14*Assumptions!$E$10*Assumptions!$E$17/365-F14*Assumptions!$E$10*Assumptions!$E$18/365)-('Balance Sheet'!F6+'Balance Sheet'!F7-'Balance Sheet'!F12) -> 15.118201
A23: Unlevered FCF | B23: =B18+B19-B20-B21 -> 95.083562 | C23: =C18+C19-C20-C21 -> 111.94668 | D23: =D18+D19-D20-D21 -> 120.57842 | E23: =E18+E19-E20-E21 -> 129.93309 | F23: =F18+F19-F20-F21 -> 140.32774
A25: DISCOUNTING & TERMINAL VALUE | B25: FY2026E | C25: FY2027E | D25: FY2028E | E25: FY2029E | F25: FY2030E | G25: Terminal
A26: Unlevered FCF | B26: =B23 -> 95.083562 | C26: =C23 -> 111.94668 | D26: =D23 -> 120.57842 | E26: =E23 -> 129.93309 | F26: =F23 -> 140.32774
A27: Period | B27: 0.5 | C27: 1.5 | D27: 2.5 | E27: 3.5 | F27: 4.5
A28: Discount Factor | B28: =1/(1+$B$6)^B27 -> 0.95016258 | C28: =1/(1+$B$6)^C27 -> 0.85781526 | D28: =1/(1+$B$6)^D27 -> 0.77444328 | E28: =1/(1+$B$6)^E27 -> 0.69917431 | F28: =1/(1+$B$6)^F27 -> 0.63122081
A29: PV of FCF | B29: =B26*B28 -> 90.344842 | C29: =C26*C28 -> 96.029575 | D29: =D26*D28 -> 93.381147 | E29: =E26*E28 -> 90.84588 | F29: =F26*F28 -> 88.57779
A31: Terminal FCF | G31: =F23*(1+$B$7) -> 144.53757
A32: Terminal Value | G32: =G31/($B$6-$B$7) -> 1861.3003
A33: PV Terminal Value | G33: =G32*F28 -> 1174.8915
A36: VALUATION SUMMARY | B36: Value
A37: PV of Explicit FCFs | B37: =SUM(B29:F29) -> 459.17923
A38: PV of Terminal Value | B38: =G33 -> 1174.8915
A39: Enterprise Value | B39: =B37+B38 -> 1634.0707
A40: Less: Net Debt | B40: =B8 -> -162.37923
A41: Equity Value | B41: =B39-B40 -> 1796.4499
A43: Share Count Proxy (M) | B43: =B9 -> 3
A44: Implied Value per Share | B44: =B41/B43 -> 598.81664
A45: Current Share Price | B45: Not available
A46: Implied Upside / (Downside) | B46: Not available
A47: Terminal Value as % of EV | B47: =B38/B39 -> 0.71899671
A48: Model Integrity | B48: =IF('Balance Sheet'!F22=0,"PASS","REVIEW") -> PASS
...

Sheet WACC
A1: ILLUSTRATIVE WACC ANALYSIS
A2: INR crores | Proxy capital structure due to no public ticker
A4: COST OF EQUITY | B4: Value | C4: Source / Rationale
A5: Risk-Free Rate | B5: 0.07 | C5: Illustrative India long-term risk-free assumption as of 16-Aug-2026
A6: Beta | B6: 1 | C6: Illustrative market beta; replace with company-specific beta
A7: Equity Risk Premium | B7: 0.055 | C7: Illustrative mature-market-plus-country-risk assumption
A9: Cost of Equity | B9: =B5+B6*B7 -> 0.125 | C9: CAPM
A11: COST OF DEBT | B11: Value | C11: Source / Rationale
A12: Interest Rate Link | B12: =Assumptions!E13 -> 0.06 | C12: Selected scenario
A13: Pre-Tax Cost of Debt | B13: =B12 -> 0.06 | C13: Model financing assumption
A14: Tax Rate | B14: =Assumptions!E12 -> 0.25 | C14: Selected scenario
A16: After-Tax Cost of Debt | B16: =B13*(1-B14) -> 0.045 | C16: Pre-tax cost × (1-tax rate)
A18: CAPITAL STRUCTURE PROXY | B18: Value | C18: Source / Rationale
A19: Gross Debt | B19: ='Balance Sheet'!F13 -> 270 | C19: FY2029 forecast balance
A20: Cash & Equivalents | B20: ='Balance Sheet'!F5 -> 432.37923 | C20: FY2029 forecast balance
A21: Net Debt / (Net Cash) | B21: =B19-B20 -> -162.37923 | C21: Debt less cash
A22: Equity Value Proxy | B22: ='Balance Sheet'!F19 -> 975.2501 | C22: FY2029 book equity; replace with market capitalization
A23: Capital Base Proxy | B23: =B19+B22 -> 1245.2501 | C23: Gross debt plus equity proxy
A25: Methodology Note | B25: WACC uses gross debt and book equity because market capitalization is unavailable.
A26: Portfolio Note | B26: Update risk-free rate, beta, ERP and market capitalization for a live-company valuation.
A28: WACC CALCULATION | B28: Weight | C28: Cost | D28: Contribution
A29: Equity | B29: =B22/B23 -> 0.78317609 | C29: =B9 -> 0.125 | D29: =B29*C29 -> 0.097897011
A30: Debt | B30: =B19/B23 -> 0.21682391 | C30: =B16 -> 0.045 | D30: =B30*C30 -> 0.0097570761
A32: WEIGHTED AVERAGE COST OF CAPITAL | D32: =SUM(D29:D30) -> 0.10765409
